Workbook

Sheet Control
A1: Grupo | B1: Código | C1: Unidad | D1: N (Excel) | E1: P25 (Excel) | F1: Mediana (Excel) | G1: P75 (Excel) | H1: N (app) | I1: P25 (app) | J1: Mediana (app) | K1: P75 (app) | L1: Diferencia precios | M1: Con postores (Excel) | N1: Mediana postores (Excel) | O1: % postor único (Excel) | P1: La Libertad (Excel) | Q1: Con postores (app) | R1: Mediana postores (app) | S1: % postor único (app) | T1: La Libertad (app) | U1: Diferencia competencia | V1: Coincide
A2: 1 | B2: 61903 | C2: Unidad | D2: =COUNT(Precios!$A$2:$A$215) | E2: =_xlfn.PERCENTILE.INC(Precios!$A$2:$A$215,0.25) | F2: =MEDIAN(Precios!$A$2:$A$215) | G2: =_xlfn.PERCENTILE.INC(Precios!$A$2:$A$215,0.75) | H2: 5 | I2: 0.198 | J2: 0.215 | K2: 0.225 | L2: =MAX(ABS(E2-I2),ABS(F2-J2),ABS(G2-K2)) | M2: =COUNT(Postores!$A$2:$A$215) | N2: =IF(M2=0,"",MEDIAN(Postores!$A$2:$A$215)) | O2: =IF(M2=0,"",COUNTIF(Postores!$A$2:$A$215,1)/M2*100) | P2: =COUNTIF(Departamentos!$A$2:$A$215,"LA LIBERTAD") | Q2: 5 | R2: 5 | S2: 0 | T2: 0 | U2: =IF(M2=0,0,MAX(ABS(N2-R2),ABS(O2-S2))) | V2: =IF(AND(D2=H2,L2<=1e-06,M2=Q2,P2=T2,U2<=1e-06),"Sí","No")
A3: 2 | B3: 388620 | C3: Unidad | D3: =COUNT(Precios!$B$2:$B$215) | E3: =_xlfn.PERCENTILE.INC(Precios!$B$2:$B$215,0.25) | F3: =MEDIAN(Precios!$B$2:$B$215) | G3: =_xlfn.PERCENTILE.INC(Precios!$B$2:$B$215,0.75) | H3: 5 | I3: 0.091 | J3: 0.1 | K3: 0.1065 | L3: =MAX(ABS(E3-I3),ABS(F3-J3),ABS(G3-K3)) | M3: =COUNT(Postores!$B$2:$B$215) | N3: =IF(M3=0,"",MEDIAN(Postores!$B$2:$B$215)) | O3: =IF(M3=0,"",COUNTIF(Postores!$B$2:$B$215,1)/M3*100) | P3: =COUNTIF(Departamentos!$B$2:$B$215,"LA LIBERTAD") | Q3: 4 | R3: 6 | S3: 0 | T3: 0 | U3: =IF(M3=0,0,MAX(ABS(N3-R3),ABS(O3-S3))) | V3: =IF(AND(D3=H3,L3<=1e-06,M3=Q3,P3=T3,U3<=1e-06),"Sí","No")
A4: 3 | B4: 362466 | C4: Metro | D4: =COUNT(Precios!$C$2:$C$215) | E4: =_xlfn.PERCENTILE.INC(Precios!$C$2:$C$215,0.25) | F4: =MEDIAN(Precios!$C$2:$C$215) | G4: =_xlfn.PERCENTILE.INC(Precios!$C$2:$C$215,0.75) | H4: 5 | I4: 945 | J4: 1190 | K4: 1648 | L4: =MAX(ABS(E4-I4),ABS(F4-J4),ABS(G4-K4)) | M4: =COUNT(Postores!$C$2:$C$215) | N4: =IF(M4=0,"",MEDIAN(Postores!$C$2:$C$215)) | O4: =IF(M4=0,"",COUNTIF(Postores!$C$2:$C$215,1)/M4*100) | P4: =COUNTIF(Departamentos!$C$2:$C$215,"LA LIBERTAD") | Q4: 5 | R4: 3 | S4: 0 | T4: 0 | U4: =IF(M4=0,0,MAX(ABS(N4-R4),ABS(O4-S4))) | V4: =IF(AND(D4=H4,L4<=1e-06,M4=Q4,P4=T4,U4<=1e-06),"Sí","No")
A5: 4 | B5: 390554 | C5: Kilogramo | D5: =COUNT(Precios!$D$2:$D$215) | E5: =_xlfn.PERCENTILE.INC(Precios!$D$2:$D$215,0.25) | F5: =MEDIAN(Precios!$D$2:$D$215) | G5: =_xlfn.PERCENTILE.INC(Precios!$D$2:$D$215,0.75) | H5: 5 | I5: 6.4660322 | J5: 6.5657565 | K5: 8.009009 | L5: =MAX(ABS(E5-I5),ABS(F5-J5),ABS(G5-K5)) | M5: =COUNT(Postores!$D$2:$D$215) | N5: =IF(M5=0,"",MEDIAN(Postores!$D$2:$D$215)) | O5: =IF(M5=0,"",COUNTIF(Postores!$D$2:$D$215,1)/M5*100) | P5: =COUNTIF(Departamentos!$D$2:$D$215,"LA LIBERTAD") | Q5: 5 | R5: 3 | S5: 20 | T5: 0 | U5: =IF(M5=0,0,MAX(ABS(N5-R5),ABS(O5-S5))) | V5: =IF(AND(D5=H5,L5<=1e-06,M5=Q5,P5=T5,U5<=1e-06),"Sí","No")
A6: 5 | B6: 392233 | C6: Unidad | D6: =COUNT(Precios!$E$2:$E$215) | E6: =_xlfn.PERCENTILE.INC(Precios!$E$2:$E$215,0.25) | F6: =MEDIAN(Precios!$E$2:$E$215) | G6: =_xlfn.PERCENTILE.INC(Precios!$E$2:$E$215,0.75) | H6: 6 | I6: 573.27586 | J6: 38996.552 | K6: 99737.5 | L6: =MAX(ABS(E6-I6),ABS(F6-J6),ABS(G6-K6)) | M6: =COUNT(Postores!$E$2:$E$215) | N6: =IF(M6=0,"",MEDIAN(Postores!$E$2:$E$215)) | O6: =IF(M6=0,"",COUNTIF(Postores!$E$2:$E$215,1)/M6*100) | P6: =COUNTIF(Departamentos!$E$2:$E$215,"LA LIBERTAD") | Q6: 6 | R6: 2.5 | S6: 16.666667 | T6: 0 | U6: =IF(M6=0,0,MAX(ABS(N6-R6),ABS(O6-S6))) | V6: =IF(AND(D6=H6,L6<=1e-06,M6=Q6,P6=T6,U6<=1e-06),"Sí","No")
A7: 6 | B7: 184418 | C7: Unidad | D7: =COUNT(Precios!$F$2:$F$215) | E7: =_xlfn.PERCENTILE.INC(Precios!$F$2:$F$215,0.25) | F7: =MEDIAN(Precios!$F$2:$F$215) | G7: =_xlfn.PERCENTILE.INC(Precios!$F$2:$F$215,0.75) | H7: 7 | I7: 22652.204 | J7: 45240 | K7: 49650 | L7: =MAX(ABS(E7-I7),ABS(F7-J7),ABS(G7-K7)) | M7: =COUNT(Postores!$F$2:$F$215) | N7: =IF(M7=0,"",MEDIAN(Postores!$F$2:$F$215)) | O7: =IF(M7=0,"",COUNTIF(Postores!$F$2:$F$215,1)/M7*100) | P7: =COUNTIF(Departamentos!$F$2:$F$215,"LA LIBERTAD") | Q7: 6 | R7: 2.5 | S7: 16.666667 | T7: 1 | U7: =IF(M7=0,0,MAX(ABS(N7-R7),ABS(O7-S7))) | V7: =IF(AND(D7=H7,L7<=1e-06,M7=Q7,P7=T7,U7<=1e-06),"Sí","No")
A8: 7 | B8: 286158 | C8: Unidad | D8: =COUNT(Precios!$G$2:$G$215) | E8: =_xlfn.PERCENTILE.INC(Precios!$G$2:$G$215,0.25) | F8: =MEDIAN(Precios!$G$2:$G$215) | G8: =_xlfn.PERCENTILE.INC(Precios!$G$2:$G$215,0.75) | H8: 8 | I8: 666.44792 | J8: 121923.5 | K8: 214425.29 | L8: =MAX(ABS(E8-I8),ABS(F8-J8),ABS(G8-K8)) | M8: =COUNT(Postores!$G$2:$G$215) | N8: =IF(M8=0,"",MEDIAN(Postores!$G$2:$G$215)) | O8: =IF(M8=0,"",COUNTIF(Postores!$G$2:$G$215,1)/M8*100) | P8: =COUNTIF(Departamentos!$G$2:$G$215,"LA LIBERTAD") | Q8: 8 | R8: 2 | S8: 50 | T8: 0 | U8: =IF(M8=0,0,MAX(ABS(N8-R8),ABS(O8-S8))) | V8: =IF(AND(D8=H8,L8<=1e-06,M8=Q8,P8=T8,U8<=1e-06),"Sí","No")
A9: 8 | B9: 60522 | C9: Unidad | D9: =COUNT(Precios!$H$2:$H$215) | E9: =_xlfn.PERCENTILE.INC(Precios!$H$2:$H$215,0.25) | F9: =MEDIAN(Precios!$H$2:$H$215) | G9: =_xlfn.PERCENTILE.INC(Precios!$H$2:$H$215,0.75) | H9: 8 | I9: 0.067925 | J9: 0.0886 | K9: 0.125 | L9: =MAX(ABS(E9-I9),ABS(F9-J9),ABS(G9-K9)) | M9: =COUNT(Postores!$H$2:$H$215) | N9: =IF(M9=0,"",MEDIAN(Postores!$H$2:$H$215)) | O9: =IF(M9=0,"",COUNTIF(Postores!$H$2:$H$215,1)/M9*100) | P9: =COUNTIF(Departamentos!$H$2:$H$215,"LA LIBERTAD") | Q9: 8 | R9: 7 | S9: 0 | T9: 0 | U9: =IF(M9=0,0,MAX(ABS(N9-R9),ABS(O9-S9))) | V9: =IF(AND(D9=H9,L9<=1e-06,M9=Q9,P9=T9,U9<=1e-06),"Sí","No")
A10: 9 | B10: 385674 | C10: Unidad | D10: =COUNT(Precios!$I$2:$I$215) | E10: =_xlfn.PERCENTILE.INC(Precios!$I$2:$I$215,0.25) | F10: =MEDIAN(Precios!$I$2:$I$215) | G10: =_xlfn.PERCENTILE.INC(Precios!$I$2:$I$215,0.75) | H10: 9 | I10: 40204.745 | J10: 44475 | K10: 50000 | L10: =MAX(ABS(E10-I10),ABS(F10-J10),ABS(G10-K10)) | M10: =COUNT(Postores!$I$2:$I$215) | N10: =IF(M10=0,"",MEDIAN(Postores!$I$2:$I$215)) | O10: =IF(M10=0,"",COUNTIF(Postores!$I$2:$I$215,1)/M10*100) | P10: =COUNTIF(Departamentos!$I$2:$I$215,"LA LIBERTAD") | Q10: 9 | R10: 3 | S10: 11.111111 | T10: 0 | U10: =IF(M10=0,0,MAX(ABS(N10-R10),ABS(O10-S10))) | V10: =IF(AND(D10=H10,L10<=1e-06,M10=Q10,P10=T10,U10<=1e-06),"Sí","No")
A11: 10 | B11: 390914 | C11: Unidad | D11: =COUNT(Precios!$J$2:$J$215) | E11: =_xlfn.PERCENTILE.INC(Precios!$J$2:$J$215,0.25) | F11: =MEDIAN(Precios!$J$2:$J$215) | G11: =_xlfn.PERCENTILE.INC(Precios!$J$2:$J$215,0.75) | H11: 9 | I11: 56760 | J11: 70900 | K11: 127170 | L11: =MAX(ABS(E11-I11),ABS(F11-J11),ABS(G11-K11)) | M11: =COUNT(Postores!$J$2:$J$215) | N11: =IF(M11=0,"",MEDIAN(Postores!$J$2:$J$215)) | O11: =IF(M11=0,"",COUNTIF(Postores!$J$2:$J$215,1)/M11*100) | P11: =COUNTIF(Departamentos!$J$2:$J$215,"LA LIBERTAD") | Q11: 9 | R11: 3 | S11: 0 | T11: 0 | U11: =IF(M11=0,0,MAX(ABS(N11-R11),ABS(O11-S11))) | V11: =IF(AND(D11=H11,L11<=1e-06,M11=Q11,P11=T11,U11<=1e-06),"Sí","No")
A12: 11 | B12: 61853 | C12: Unidad | D12: =COUNT(Precios!$K$2:$K$215) | E12: =_xlfn.PERCENTILE.INC(Precios!$K$2:$K$215,0.25) | F12: =MEDIAN(Precios!$K$2:$K$215) | G12: =_xlfn.PERCENTILE.INC(Precios!$K$2:$K$215,0.75) | H12: 10 | I12: 4.4124234 | J12: 7.175 | K12: 9.86 | L12: =MAX(ABS(E12-I12),ABS(F12-J12),ABS(G12-K12)) | M12: =COUNT(Postores!$K$2:$K$215) | N12: =IF(M12=0,"",MEDIAN(Postores!$K$2:$K$215)) | O12: =IF(M12=0,"",COUNTIF(Postores!$K$2:$K$215,1)/M12*100) | P12: =COUNTIF(Departamentos!$K$2:$K$215,"LA LIBERTAD") | Q12: 10 | R12: 3 | S12: 10 | T12: 2 | U12: =IF(M12=0,0,MAX(ABS(N12-R12),ABS(O12-S12))) | V12: =IF(AND(D12=H12,L12<=1e-06,M12=Q12,P12=T12,U12<=1e-06),"Sí","No")
A13: 12 | B13: 391873 | C13: Unidad | D13: =COUNT(Precios!$L$2:$L$215) | E13: =_xlfn.PERCENTILE.INC(Precios!$L$2:$L$215,0.25) | F13: =MEDIAN(Precios!$L$2:$L$215) | G13: =_xlfn.PERCENTILE.INC(Precios!$L$2:$L$215,0.75) | H13: 11 | I13: 39281.667 | J13: 65995 | K13: 79750 | L13: =MAX(ABS(E13-I13),ABS(F13-J13),ABS(G13-K13)) | M13: =COUNT(Postores!$L$2:$L$215) | N13: =IF(M13=0,"",MEDIAN(Postores!$L$2:$L$215)) | O13: =IF(M13=0,"",COUNTIF(Postores!$L$2:$L$215,1)/M13*100) | P13: =COUNTIF(Departamentos!$L$2:$L$215,"LA LIBERTAD") | Q13: 11 | R13: 4 | S13: 18.181818 | T13: 1 | U13: =IF(M13=0,0,MAX(ABS(N13-R13),ABS(O13-S13))) | V13: =IF(AND(D13=H13,L13<=1e-06,M13=Q13,P13=T13,U13<=1e-06),"Sí","No")
A14: 13 | B14: 184824 | C14: Unidad | D14: =COUNT(Precios!$M$2:$M$215) | E14: =_xlfn.PERCENTILE.INC(Precios!$M$2:$M$215,0.25) | F14: =MEDIAN(Precios!$M$2:$M$215) | G14: =_xlfn.PERCENTILE.INC(Precios!$M$2:$M$215,0.75) | H14: 11 | I14: 548900 | J14: 594318.5 | K14: 666000 | L14: =MAX(ABS(E14-I14),ABS(F14-J14),ABS(G14-K14)) | M14: =COUNT(Postores!$M$2:$M$215) | N14: =IF(M14=0,"",MEDIAN(Postores!$M$2:$M$215)) | O14: =IF(M14=0,"",COUNTIF(Postores!$M$2:$M$215,1)/M14*100) | P14: =COUNTIF(Departamentos!$M$2:$M$215,"LA LIBERTAD") | Q14: 11 | R14: 1 | S14: 54.545455 | T14: 1 | U14: =IF(M14=0,0,MAX(ABS(N14-R14),ABS(O14-S14))) | V14: =IF(AND(D14=H14,L14<=1e-06,M14=Q14,P14=T14,U14<=1e-06),"Sí","No")
A15: 14 | B15: 2453 | C15: Kilogramo | D15: =COUNT(Precios!$N$2:$N$215) | E15: =_xlfn.PERCENTILE.INC(Precios!$N$2:$N$215,0.25) | F15: =MEDIAN(Precios!$N$2:$N$215) | G15: =_xlfn.PERCENTILE.INC(Precios!$N$2:$N$215,0.75) | H15: 11 | I15: 3.49 | J15: 4.06512 | K15: 5.45 | L15: =MAX(ABS(E15-I15),ABS(F15-J15),ABS(G15-K15)) | M15: =COUNT(Postores!$N$2:$N$215) | N15: =IF(M15=0,"",MEDIAN(Postores!$N$2:$N$215)) | O15: =IF(M15=0,"",COUNTIF(Postores!$N$2:$N$215,1)/M15*100) | P15: =COUNTIF(Departamentos!$N$2:$N$215,"LA LIBERTAD") | Q15: 11 | R15: 3 | S15: 0 | T15: 0 | U15: =IF(M15=0,0,MAX(ABS(N15-R15),ABS(O15-S15))) | V15: =IF(AND(D15=H15,L15<=1e-06,M15=Q15,P15=T15,U15<=1e-06),"Sí","No")
A16: 15 | B16: 369538 | C16: Kilogramo | D16: =COUNT(Precios!$O$2:$O$215) | E16: =_xlfn.PERCENTILE.INC(Precios!$O$2:$O$215,0.25) | F16: =MEDIAN(Precios!$O$2:$O$215) | G16: =_xlfn.PERCENTILE.INC(Precios!$O$2:$O$215,0.75) | H16: 11 | I16: 4.275 | J16: 4.8 | K16: 5.07 | L16: =MAX(ABS(E16-I16),ABS(F16-J16),ABS(G16-K16)) | M16: =COUNT(Postores!$O$2:$O$215) | N16: =IF(M16=0,"",MEDIAN(Postores!$O$2:$O$215)) | O16: =IF(M16=0,"",COUNTIF(Postores!$O$2:$O$215,1)/M16*100) | P16: =COUNTIF(Departamentos!$O$2:$O$215,"LA LIBERTAD") | Q16: 11 | R16: 3 | S16: 9.0909091 | T16: 0 | U16: =IF(M16=0,0,MAX(ABS(N16-R16),ABS(O16-S16))) | V16: =IF(AND(D16=H16,L16<=1e-06,M16=Q16,P16=T16,U16<=1e-06),"Sí","No")
A17: 16 | B17: 367431 | C17: Unidad | D17: =COUNT(Precios!$P$2:$P$215) | E17: =_xlfn.PERCENTILE.INC(Precios!$P$2:$P$215,0.25) | F17: =MEDIAN(Precios!$P$2:$P$215) | G17: =_xlfn.PERCENTILE.INC(Precios!$P$2:$P$215,0.75) | H17: 12 | I17: 140.69 | J17: 151.03 | K17: 568.8264 | L17: =MAX(ABS(E17-I17),ABS(F17-J17),ABS(G17-K17)) | M17: =COUNT(Postores!$P$2:$P$215) | N17: =IF(M17=0,"",MEDIAN(Postores!$P$2:$P$215)) | O17: =IF(M17=0,"",COUNTIF(Postores!$P$2:$P$215,1)/M17*100) | P17: =COUNTIF(Departamentos!$P$2:$P$215,"LA LIBERTAD") | Q17: 12 | R17: 2 | S17: 16.666667 | T17: 1 | U17: =IF(M17=0,0,MAX(ABS(N17-R17),ABS(O17-S17))) | V17: =IF(AND(D17=H17,L17<=1e-06,M17=Q17,P17=T17,U17<=1e-06),"Sí","No")
A18: 17 | B18: 211221 | C18: Millar | D18: =COUNT(Precios!$Q$2:$Q$215) | E18: =_xlfn.PERCENTILE.INC(Precios!$Q$2:$Q$215,0.25) | F18: =MEDIAN(Precios!$Q$2:$Q$215) | G18: =_xlfn.PERCENTILE.INC(Precios!$Q$2:$Q$215,0.75) | H18: 12 | I18: 150 | J18: 153.5 | K18: 162.375 | L18: =MAX(ABS(E18-I18),ABS(F18-J18),ABS(G18-K18)) | M18: =COUNT(Postores!$Q$2:$Q$215) | N18: =IF(M18=0,"",MEDIAN(Postores!$Q$2:$Q$215)) | O18: =IF(M18=0,"",COUNTIF(Postores!$Q$2:$Q$215,1)/M18*100) | P18: =COUNTIF(Departamentos!$Q$2:$Q$215,"LA LIBERTAD") | Q18: 12 | R18: 3 | S18: 8.3333333 | T18: 0 | U18: =IF(M18=0,0,MAX(ABS(N18-R18),ABS(O18-S18))) | V18: =IF(AND(D18=H18,L18<=1e-06,M18=Q18,P18=T18,U18<=1e-06),"Sí","No")
A19: 18 | B19: 60267 | C19: Unidad | D19: =COUNT(Precios!$R$2:$R$215) | E19: =_xlfn.PERCENTILE.INC(Precios!$R$2:$R$215,0.25) | F19: =MEDIAN(Precios!$R$2:$R$215) | G19: =_xlfn.PERCENTILE.INC(Precios!$R$2:$R$215,0.75) | H19: 12 | I19: 29.5 | J19: 31.5 | K19: 35 | L19: =MAX(ABS(E19-I19),ABS(F19-J19),ABS(G19-K19)) | M19: =COUNT(Postores!$R$2:$R$215) | N19: =IF(M19=0,"",MEDIAN(Postores!$R$2:$R$215)) | O19: =IF(M19=0,"",COUNTIF(Postores!$R$2:$R$215,1)/M19*100) | P19: =COUNTIF(Departamentos!$R$2:$R$215,"LA LIBERTAD") | Q19: 12 | R19: 2.5 | S19: 41.666667 | T19: 0 | U19: =IF(M19=0,0,MAX(ABS(N19-R19),ABS(O19-S19))) | V19: =IF(AND(D19=H19,L19<=1e-06,M19=Q19,P19=T19,U19<=1e-06),"Sí","No")
A20: 19 | B20: 380409 | C20: Unidad | D20: =COUNT(Precios!$S$2:$S$215) | E20: =_xlfn.PERCENTILE.INC(Precios!$S$2:$S$215,0.25) | F20: =MEDIAN(Precios!$S$2:$S$215) | G20: =_xlfn.PERCENTILE.INC(Precios!$S$2:$S$215,0.75) | H20: 16 | I20: 43281.497 | J20: 58125 | K20: 90476.027 | L20: =MAX(ABS(E20-I20),ABS(F20-J20),ABS(G20-K20)) | M20: =COUNT(Postores!$S$2:$S$215) | N20: =IF(M20=0,"",MEDIAN(Postores!$S$2:$S$215)) | O20: =IF(M20=0,"",COUNTIF(Postores!$S$2:$S$215,1)/M20*100) | P20: =COUNTIF(Departamentos!$S$2:$S$215,"LA LIBERTAD") | Q20: 16 | R20: 3 | S20: 31.25 | T20: 0 | U20: =IF(M20=0,0,MAX(ABS(N20-R20),ABS(O20-S20))) | V20: =IF(AND(D20=H20,L20<=1e-06,M20=Q20,P20=T20,U20<=1e-06),"Sí","No")
A21: 20 | B21: 59202 | C21: Unidad | D21: =COUNT(Precios!$T$2:$T$215) | E21: =_xlfn.PERCENTILE.INC(Precios!$T$2:$T$215,0.25) | F21: =MEDIAN(Precios!$T$2:$T$215) | G21: =_xlfn.PERCENTILE.INC(Precios!$T$2:$T$215,0.75) | H21: 17 | I21: 1.55 | J21: 1.8 | K21: 2.35 | L21: =MAX(ABS(E21-I21),ABS(F21-J21),ABS(G21-K21)) | M21: =COUNT(Postores!$T$2:$T$215) | N21: =IF(M21=0,"",MEDIAN(Postores!$T$2:$T$215)) | O21: =IF(M21=0,"",COUNTIF(Postores!$T$2:$T$215,1)/M21*100) | P21: =COUNTIF(Departamentos!$T$2:$T$215,"LA LIBERTAD") | Q21: 17 | R21: 6 | S21: 0 | T21: 0 | U21: =IF(M21=0,0,MAX(ABS(N21-R21),ABS(O21-S21))) | V21: =IF(AND(D21=H21,L21<=1e-06,M21=Q21,P21=T21,U21<=1e-06),"Sí","No")
A22: 21 | B22: 178724 | C22: Unidad | D22: =COUNT(Precios!$U$2:$U$215) | E22: =_xlfn.PERCENTILE.INC(Precios!$U$2:$U$215,0.25) | F22: =MEDIAN(Precios!$U$2:$U$215) | G22: =_xlfn.PERCENTILE.INC(Precios!$U$2:$U$215,0.75) | H22: 30 | I22: 27.199 | J22: 34.15 | K22: 598.75 | L22: =MAX(ABS(E22-I22),ABS(F22-J22),ABS(G22-K22)) | M22: =COUNT(Postores!$U$2:$U$215) | N22: =IF(M22=0,"",MEDIAN(Postores!$U$2:$U$215)) | O22: =IF(M22=0,"",COUNTIF(Postores!$U$2:$U$215,1)/M22*100) | P22: =COUNTIF(Departamentos!$U$2:$U$215,"LA LIBERTAD") | Q22: 30 | R22: 1 | S22: 76.666667 | T22: 1 | U22: =IF(M22=0,0,MAX(ABS(N22-R22),ABS(O22-S22))) | V22: =IF(AND(D22=H22,L22<=1e-06,M22=Q22,P22=T22,U22<=1e-06),"Sí","No")
A23: 22 | B23: 329939 | C23: Galon | D23: =COUNT(Precios!$V$2:$V$215) | E23: =_xlfn.PERCENTILE.INC(Precios!$V$2:$V$215,0.25) | F23: =MEDIAN(Precios!$V$2:$V$215) | G23: =_xlfn.PERCENTILE.INC(Precios!$V$2:$V$215,0.75) | H23: 32 | I23: 13.864013 | J23: 15.2455 | K23: 18.365457 | L23: =MAX(ABS(E23-I23),ABS(F23-J23),ABS(G23-K23)) | M23: =COUNT(Postores!$V$2:$V$215) | N23: =IF(M23=0,"",MEDIAN(Postores!$V$2:$V$215)) | O23: =IF(M23=0,"",COUNTIF(Postores!$V$2:$V$215,1)/M23*100) | P23: =COUNTIF(Departamentos!$V$2:$V$215,"LA LIBERTAD") | Q23: 32 | R23: 6 | S23: 3.125 | T23: 0 | U23: =IF(M23=0,0,MAX(ABS(N23-R23),ABS(O23-S23))) | V23: =IF(AND(D23=H23,L23<=1e-06,M23=Q23,P23=T23,U23<=1e-06),"Sí","No")
A24: 23 | B24: 385153 | C24: Unidad | D24: =COUNT(Precios!$W$2:$W$215) | E24: =_xlfn.PERCENTILE.INC(Precios!$W$2:$W$215,0.25) | F24: =MEDIAN(Precios!$W$2:$W$215) | G24: =_xlfn.PERCENTILE.INC(Precios!$W$2:$W$215,0.75) | H24: 33 | I24: 9.2 | J24: 17.553443 | K24: 28 | L24: =MAX(ABS(E24-I24),ABS(F24-J24),ABS(G24-K24)) | M24: =COUNT(Postores!$W$2:$W$215) | N24: =IF(M24=0,"",MEDIAN(Postores!$W$2:$W$215)) | O24: =IF(M24=0,"",COUNTIF(Postores!$W$2:$W$215,1)/M24*100) | P24: =COUNTIF(Departamentos!$W$2:$W$215,"LA LIBERTAD") | Q24: 33 | R24: 5 | S24: 0 | T24: 1 | U24: =IF(M24=0,0,MAX(ABS(N24-R24),ABS(O24-S24))) | V24: =IF(AND(D24=H24,L24<=1e-06,M24=Q24,P24=T24,U24<=1e-06),"Sí","No")
A25: 24 | B25: 151276 | C25: M2 | D25: =COUNT(Precios!$X$2:$X$215) | E25: =_xlfn.PERCENTILE.INC(Precios!$X$2:$X$215,0.25) | F25: =MEDIAN(Precios!$X$2:$X$215) | G25: =_xlfn.PERCENTILE.INC(Precios!$X$2:$X$215,0.75) | H25: 62 | I25: 69.201571 | J25: 109.87805 | K25: 148.92779 | L25: =MAX(ABS(E25-I25),ABS(F25-J25),ABS(G25-K25)) | M25: =COUNT(Postores!$X$2:$X$215) | N25: =IF(M25=0,"",MEDIAN(Postores!$X$2:$X$215)) | O25: =IF(M25=0,"",COUNTIF(Postores!$X$2:$X$215,1)/M25*100) | P25: =COUNTIF(Departamentos!$X$2:$X$215,"LA LIBERTAD") | Q25: 62 | R25: 3 | S25: 6.4516129 | T25: 0 | U25: =IF(M25=0,0,MAX(ABS(N25-R25),ABS(O25-S25))) | V25: =IF(AND(D25=H25,L25<=1e-06,M25=Q25,P25=T25,U25<=1e-06),"Sí","No")
A26: 25 | B26: 64564 | C26: Unidad | D26: =COUNT(Precios!$Y$2:$Y$215) | E26: =_xlfn.PERCENTILE.INC(Precios!$Y$2:$Y$215,0.25) | F26: =MEDIAN(Precios!$Y$2:$Y$215) | G26: =_xlfn.PERCENTILE.INC(Precios!$Y$2:$Y$215,0.75) | H26: 63 | I26: 469395 | J26: 490000 | K26: 544840.58 | L26: =MAX(ABS(E26-I26),ABS(F26-J26),ABS(G26-K26)) | M26: =COUNT(Postores!$Y$2:$Y$215) | N26: =IF(M26=0,"",MEDIAN(Postores!$Y$2:$Y$215)) | O26: =IF(M26=0,"",COUNTIF(Postores!$Y$2:$Y$215,1)/M26*100) | P26: =COUNTIF(Departamentos!$Y$2:$Y$215,"LA LIBERTAD") | Q26: 63 | R26: 1 | S26: 57.142857 | T26: 5 | U26: =IF(M26=0,0,MAX(ABS(N26-R26),ABS(O26-S26))) | V26: =IF(AND(D26=H26,L26<=1e-06,M26=Q26,P26=T26,U26<=1e-06),"Sí","No")
A27: 26 | B27: 65085 | C27: Unidad | D27: =COUNT(Precios!$Z$2:$Z$215) | E27: =_xlfn.PERCENTILE.INC(Precios!$Z$2:$Z$215,0.25) | F27: =MEDIAN(Precios!$Z$2:$Z$215) | G27: =_xlfn.PERCENTILE.INC(Precios!$Z$2:$Z$215,0.75) | H27: 72 | I27: 284975 | J27: 316225 | K27: 355600 | L27: =MAX(ABS(E27-I27),ABS(F27-J27),ABS(G27-K27)) | M27: =COUNT(Postores!$Z$2:$Z$215) | N27: =IF(M27=0,"",MEDIAN(Postores!$Z$2:$Z$215)) | O27: =IF(M27=0,"",COUNTIF(Postores!$Z$2:$Z$215,1)/M27*100) | P27: =COUNTIF(Departamentos!$Z$2:$Z$215,"LA LIBERTAD") | Q27: 72 | R27: 1 | S27: 66.666667 | T27: 2 | U27: =IF(M27=0,0,MAX(ABS(N27-R27),ABS(O27-S27))) | V27: =IF(AND(D27=H27,L27<=1e-06,M27=Q27,P27=T27,U27<=1e-06),"Sí","No")
A28: 27 | B28: 259255 | C28: Unidad | D28: =COUNT(Precios!$AA$2:$AA$215) | E28: =_xlfn.PERCENTILE.INC(Precios!$AA$2:$AA$215,0.25) | F28: =MEDIAN(Precios!$AA$2:$AA$215) | G28: =_xlfn.PERCENTILE.INC(Precios!$AA$2:$AA$215,0.75) | H28: 86 | I28: 25.9775 | J28: 30 | K28: 31.450293 | L28: =MAX(ABS(E28-I28),ABS(F28-J28),ABS(G28-K28)) | M28: =COUNT(Postores!$AA$2:$AA$215) | N28: =IF(M28=0,"",MEDIAN(Postores!$AA$2:$AA$215)) | O28: =IF(M28=0,"",COUNTIF(Postores!$AA$2:$AA$215,1)/M28*100) | P28: =COUNTIF(Departamentos!$AA$2:$AA$215,"LA LIBERTAD") | Q28: 86 | R28: 4 | S28: 0 | T28: 8 | U28: =IF(M28=0,0,MAX(ABS(N28-R28),ABS(O28-S28))) | V28: =IF(AND(D28=H28,L28<=1e-06,M28=Q28,P28=T28,U28<=1e-06),"Sí","No")
A29: 28 | B29: 2675 | C29: Kilogramo | D29: =COUNT(Precios!$AB$2:$AB$215) | E29: =_xlfn.PERCENTILE.INC(Precios!$AB$2:$AB$215,0.25) | F29: =MEDIAN(Precios!$AB$2:$AB$215) | G29: =_xlfn.PERCENTILE.INC(Precios!$AB$2:$AB$215,0.75) | H29: 121 | I29: 3.4018119 | J29: 4.26 | K29: 5.6004673 | L29: =MAX(ABS(E29-I29),ABS(F29-J29),ABS(G29-K29)) | M29: =COUNT(Postores!$AB$2:$AB$215) | N29: =IF(M29=0,"",MEDIAN(Postores!$AB$2:$AB$215)) | O29: =IF(M29=0,"",COUNTIF(Postores!$AB$2:$AB$215,1)/M29*100) | P29: =COUNTIF(Departamentos!$AB$2:$AB$215,"LA LIBERTAD") | Q29: 121 | R29: 15 | S29: 12.396694 | T29: 6 | U29: =IF(M29=0,0,MAX(ABS(N29-R29),ABS(O29-S29))) | V29: =IF(AND(D29=H29,L29<=1e-06,M29=Q29,P29=T29,U29<=1e-06),"Sí","No")
A30: 29 | B30: 385506 | C30: Unidad | D30: =COUNT(Precios!$AC$2:$AC$215) | E30: =_xlfn.PERCENTILE.INC(Precios!$AC$2:$AC$215,0.25) | F30: =MEDIAN(Precios!$AC$2:$AC$215) | G30: =_xlfn.PERCENTILE.INC(Precios!$AC$2:$AC$215,0.75) | H30: 127 | I30: 941450 | J30: 1143871 | K30: 1304284.9 | L30: =MAX(ABS(E30-I30),ABS(F30-J30),ABS(G30-K30)) | M30: =COUNT(Postores!$AC$2:$AC$215) | N30: =IF(M30=0,"",MEDIAN(Postores!$AC$2:$AC$215)) | O30: =IF(M30=0,"",COUNTIF(Postores!$AC$2:$AC$215,1)/M30*100) | P30: =COUNTIF(Departamentos!$AC$2:$AC$215,"LA LIBERTAD") | Q30: 126 | R30: 1 | S30: 63.492063 | T30: 5 | U30: =IF(M30=0,0,MAX(ABS(N30-R30),ABS(O30-S30))) | V30: =IF(AND(D30=H30,L30<=1e-06,M30=Q30,P30=T30,U30<=1e-06),"Sí","No")
A31: 30 | B31: 134565 | C31: Unidad | D31: =COUNT(Precios!$AD$2:$AD$215) | E31: =_xlfn.PERCENTILE.INC(Precios!$AD$2:$AD$215,0.25) | F31: =MEDIAN(Precios!$AD$2:$AD$215) | G31: =_xlfn.PERCENTILE.INC(Precios!$AD$2:$AD$215,0.75) | H31: 214 | I31: 2.0992415 | J31: 2.2 | K31: 2.3725 | L31: =MAX(ABS(E31-I31),ABS(F31-J31),ABS(G31-K31)) | M31: =COUNT(Postores!$AD$2:$AD$215) | N31: =IF(M31=0,"",MEDIAN(Postores!$AD$2:$AD$215)) | O31: =IF(M31=0,"",COUNTIF(Postores!$AD$2:$AD$215,1)/M31*100) | P31: =COUNTIF(Departamentos!$AD$2:$AD$215,"LA LIBERTAD") | Q31: 214 | R31: 2 | S31: 49.53271 | T31: 2 | U31: =IF(M31=0,0,MAX(ABS(N31-R31),ABS(O31-S31))) | V31: =IF(AND(D31=H31,L31<=1e-06,M31=Q31,P31=T31,U31<=1e-06),"Sí","No")
A33: Discrepancias | B33: =COUNTIF(V2:V31,"No")
A34: Columnas en azul: valores calculados por el agente analista. Columnas (Excel): fórmulas sobre las hojas Precios, Postores y Departamentos.

Sheet Precios
A1: 61903 | B1: 388620 | C1: 362466 | D1: 390554 | E1: 392233 | F1: 184418 | G1: 286158 | H1: 60522 | I1: 385674 | J1: 390914 | K1: 61853 | L1: 391873 | M1: 184824 | N1: 2453 | O1: 369538 | P1: 367431 | Q1: 211221 | R1: 60267 | S1: 380409 | T1: 59202 | U1: 178724 | V1: 329939 | W1: 385153 | X1: 151276 | Y1: 64564 | Z1: 65085 | AA1: 259255 | AB1: 2675 | AC1: 385506 | AD1: 134565
A2: 0.18 | B2: 0.087 | C2: 506 | D2: 5.7599999 | E2: 500 | F2: 7800 | G2: 213 | H2: 0.059 | I2: 32900 | J2: 580.55556 | K2: 3.127 | L2: 3144 | M2: 12646.201 | N2: 2.3181912 | O2: 3.91 | P2: 51.015901 | Q2: 80 | R2: 8.19 | S2: 19550 | T2: 1.15 | U2: 21.83 | V2: 8.0999263 | W2: 0.96399999 | X2: 18 | Y2: 24333.333 | Z2: 150000 | AA2: 23.65 | AB2: 2.72 | AC2: 585000 | AD2: 0.011646913
A3: 0.198 | B3: 0.091 | C3: 945 | D3: 6.4660322 | E3: 500 | F3: 18550 | G3: 415.79167 | H3: 0.0647 | I3: 36863.755 | J3: 12142.857 | K3: 3.186 | L3: 5029.77 | M3: 245000 | N3: 2.5016628 | O3: 3.9957173 | P3: 109.50542 | Q3: 148.57 | R3: 25 | S3: 21800 | T3: 1.25 | U3: 22.8 | V3: 13.149999 | W3: 1.065 | X3: 25 | Y3: 60177.517 | Z3: 157500 | AA3: 24.17 | AB3: 2.72 | AC3: 623000 | AD3: 1.775
A4: 0.215 | B4: 0.1 | C4: 1190 | D4: 6.5657565 | E4: 793.10345 | F4: 26754.408 | G4: 750 | H4: 0.069 | I4: 40204.745 | J4: 56760 | K4: 4.012 | L4: 35100 | M4: 548800 | N4: 3.3 | O4: 4.15 | P4: 110 | Q4: 150 | R4: 28 | S4: 21971.16 | T4: 1.3903196 | U4: 22.96 | V4: 13.3 | W4: 1.17 | X4: 29.6 | Y4: 73850 | Z4: 187999 | AA4: 24.25 | AB4: 2.72 | AC4: 675000 | AD4: 1.7818576
A5: 0.225 | B5: 0.1065 | C5: 1648 | D5: 8.009009 | E5: 77200 | F5: 45240 | G5: 121552.39 | H5: 0.084 | I5: 44325.59 | J5: 60480 | K5: 5.6136937 | L5: 43463.333 | M5: 549000 | N5: 3.68 | O5: 4.4 | P5: 150.92 | Q5: 150 | R5: 30 | S5: 40585.99 | T5: 1.3991828 | U5: 23.95 | V5: 13.4 | W5: 1.239 | X5: 44.9 | Y5: 92600 | Z5: 188690 | AA5: 24.3 | AB5: 2.72 | AC5: 675000 | AD5: 1.7889998
A6: 0.22670917 | B6: 0.14 | C6: 317977.4 | D6: 8.564248 | E6: 107250 | F6: 46000 | G6: 122294.61 | H6: 0.0932 | I6: 44475 | J6: 70900 | K6: 5.9 | L6: 54500 | M6: 593000 | N6: 3.81 | O6: 4.5 | P6: 150.92 | Q6: 151 | R6: 30 | S6: 44180 | T6: 1.55 | U6: 24.78 | V6: 13.4 | W6: 1.2508 | X6: 45 | Y6: 164000 | Z6: 198400 | AA6: 24.363057 | AB6: 2.93 | AC6: 692000 | AD6: 1.7957201
E7: 114760 | F7: 53300 | G7: 205462.93 | H7: 0.12 | I7: 49994 | J7: 76000 | K7: 8.45 | L7: 65995 | M7: 594318.5 | N7: 4.06512 | O7: 4.8 | P7: 151.03 | Q7: 152 | R7: 30 | S7: 47120 | T7: 1.6444444 | U7: 25.96 | V7: 13.46 | W7: 1.64 | X7: 46.25 | Y7: 251764.8 | Z7: 230000 | AA7: 24.45 | AB7: 2.93 | AC7: 750000 | AD7: 1.7990019
F8: 111000 | G8: 241312.36 | H8: 0.14 | I8: 50000 | J8: 127170 | K8: 9.44 | L8: 70000 | M8: 616000 | N8: 4.3 | O8: 4.98 | P8: 151.03 | Q8: 155 | R8: 33 | S8: 48650 | T8: 1.65 | U8: 26.5 | V8: 13.8 | W8: 1.67 | X8: 49 | Y8: 393750 | Z8: 232470 | AA8: 24.462189 | AB8: 2.99 | AC8: 799413.42 | AD8: 1.8720681
G9: 655550.99 | H9: 0.19833333 | I9: 71000 | J9: 160900 | K9: 10 | L9: 76500 | M9: 649000 | N9: 4.9 | O9: 5 | P9: 225.9458 | Q9: 160 | R9: 35 | S9: 54000 | T9: 1.6666667 | U9: 27.14 | V9: 13.8 | W9: 3.15 | X9: 49 | Y9: 422049.3 | Z9: 240100 | AA9: 24.5 | AB9: 3 | AC9: 810000 | AD9: 1.88
I10: 4360652.1 | J10: 418915 | K10: 10.469 | L10: 83000 | M10: 683000 | N10: 6 | O10: 5.14 | P10: 388.61702 | Q10: 162 | R10: 35 | S10: 62250 | T10: 1.8 | U10: 27.376 | V10: 13.88535 | W10: 9.2 | X10: 50 | Y10: 424800 | Z10: 246459 | AA10: 24.89 | AB10: 3 | AC10: 826068 | AD10: 1.89
K11: 10.47 | L11: 88068.1 | M11: 881000 | N11: 16.024444 | O11: 5.2 | P11: 1109.4545 | Q11: 163.5 | R11: 35 | S11: 67450 | T11: 1.8 | U11: 27.6 | V11: 13.894325 | W11: 12.54 | X11: 50 | Y11: 449219.63 | Z11: 255000 | AA11: 24.97 | AB11: 3 | AC11: 834000 | AD11: 1.89
L12: 140000 | M12: 900000 | N12: 48.618 | O12: 5.4 | P12: 61755 | Q12: 165 | R12: 38 | S12: 77734.22 | T12: 1.9230769 | U12: 29.22 | V12: 14.2 | W12: 13.192401 | X12: 52.2 | Y12: 450000 | Z12: 264320 | AA12: 25 | AB12: 3 | AC12: 842482.48 | AD12: 1.9
P13: 91392 | Q13: 174.93333 | R13: 38 | S13: 85000 | T13: 2.34 | U13: 29.5 | V13: 14.2 | W13: 14.37 | X13: 58.5 | Y13: 458120.72 | Z13: 264880.5 | AA13: 25.244976 | AB13: 3 | AC13: 846533 | AD13: 1.93
S14: 106904.11 | T14: 2.35 | U14: 31.624 | V14: 14.435406 | W14: 14.4 | X14: 59.344553 | Y14: 460000 | Z14: 269900 | AA14: 25.26 | AB14: 3.0959549 | AC14: 860000 | AD14: 1.94
S15: 136600 | T15: 2.39 | U15: 32.167 | V15: 14.459 | W15: 14.69 | X15: 60 | Y15: 460613 | Z15: 272800 | AA15: 25.266667 | AB15: 3.1 | AC15: 860000 | AD15: 1.94
S16: 150000 | T16: 2.4 | U16: 33.8 | V16: 14.5 | W16: 15.5 | X16: 65 | Y16: 465000 | Z16: 272863.2 | AA16: 25.39 | AB16: 3.1 | AC16: 869000 | AD16: 1.95
S17: 377800.04 | T17: 2.4 | U17: 34.5 | V17: 15.241 | W17: 15.9 | X17: 68.935428 | Y17: 468790 | Z17: 273588.9 | AA17: 25.4 | AB17: 3.1 | AC17: 880000 | AD17: 1.95
T18: 2.5 | U18: 35.4 | V18: 15.25 | W18: 17.553443 | X18: 70 | Y18: 470000 | Z18: 279500 | AA18: 25.46 | AB18: 3.14 | AC18: 880000 | AD18: 1.95
U19: 36.292195 | V19: 15.8 | W19: 18.92 | X19: 71.839064 | Y19: 470000 | Z19: 284900 | AA19: 25.71428 | AB19: 3.1990012 | AC19: 880280 | AD19: 1.95
U20: 37 | V20: 16.42 | W20: 20 | X20: 80.8 | Y20: 470000 | Z20: 285000 | AA20: 25.8 | AB20: 3.25 | AC20: 885000 | AD20: 1.95
U21: 39 | V21: 16.75 | W21: 21.5 | X21: 81.032765 | Y21: 470040.73 | Z21: 290309 | AA21: 25.81 | AB21: 3.34 | AC21: 896900 | AD21: 1.95
U22: 43.66 | V22: 16.834765 | W22: 22.319867 | X22: 82.6 | Y22: 475000 | Z22: 293309 | AA22: 25.849558 | AB22: 3.4006326 | AC22: 900000 | AD22: 1.96
U23: 46 | V23: 17.8 | W23: 23.98 | X23: 84.832822 | Y23: 475000 | Z23: 295000 | AA23: 25.97 | AB23: 3.4006326 | AC23: 905000 | AD23: 1.97
U24: 783 | V24: 18 | W24: 24 | X24: 88 | Y24: 480000 | Z24: 295000 | AA24: 26 | AB24: 3.4018119 | AC24: 910000 | AD24: 1.97
U25: 72000 | V25: 18.3 | W25: 24.6 | X25: 89 | Y25: 480000 | Z25: 295425 | AA25: 26.123596 | AB25: 3.4018119 | AC25: 910000 | AD25: 1.98
U26: 107175 | V26: 18.561829 | W26: 28 | X26: 90 | Y26: 480000 | Z26: 296876.2 | AA26: 26.13 | AB26: 3.4018119 | AC26: 920000 | AD26: 1.98
U27: 136800 | V27: 18.831169 | W27: 29.1 | X27: 92 | Y27: 480000 | Z27: 298900 | AA27: 26.193957 | AB27: 3.4018119 | AC27: 925000 | AD27: 1.98
U28: 228480 | V28: 19.137792 | W28: 32.5 | X28: 93 | Y28: 481812.41 | Z28: 299000 | AA28: 26.5875 | AB28: 3.4018119 | AC28: 930000 | AD28: 1.985
U29: 409932 | V29: 19.16 | W29: 36 | X29: 95 | Y29: 485000 | Z29: 299500 | AA29: 26.65 | AB29: 3.4018119 | AC29: 930000 | AD29: 1.985
U30: 411130 | V30: 19.165178 | W30: 41.6 | X30: 97.4 | Y30: 485000 | Z30: 299900 | AA30: 27 | AB30: 3.4018119 | AC30: 932223.6 | AD30: 1.9899998
U31: 741600 | V31: 20 | W31: 74.252888 | X31: 107.994 | Y31: 485000 | Z31: 299900 | AA31: 27 | AB31: 3.4018119 | AC31: 932282.6 | AD31: 1.99
V32: 22.67 | W32: 139.72603 | X32: 109.7561 | Y32: 486101 | Z32: 300000 | AA32: 27 | AB32: 3.4018119 | AC32: 935000 | AD32: 1.99
V33: 22.857143 | W33: 9125 | X33: 110 | Y33: 490000 | Z33: 309396 | AA33: 27.3 | AB33: 3.4018119 | AC33: 935000 | AD33: 1.99
W34: 99944 | X34: 111.58247 | Y34: 490000 | Z34: 310000 | AA34: 28.2 | AB34: 3.4018119 | AC34: 947900 | AD34: 1.99
X35: 111.6 | Y35: 498375.36 | Z35: 313433 | AA35: 28.274668 | AB35: 3.4018119 | AC35: 954618 | AD35: 1.99
X36: 111.76471 | Y36: 498984.95 | Z36: 314538 | AA36: 28.399769 | AB36: 3.4018119 | AC36: 970000 | AD36: 1.99
X37: 114.36122 | Y37: 508593.39 | Z37: 315000 | AA37: 28.488095 | AB37: 3.4018119 | AC37: 990964 | AD37: 1.99
X38: 116.39344 | Y38: 510137.01 | Z38: 317450 | AA38: 28.9 | AB38: 3.4018119 | AC38: 1004416 | AD38: 1.995
X39: 118.06907 | Y39: 520000 | Z39: 320877.4 | AA39: 29 | AB39: 3.4018119 | AC39: 1025892 | AD39: 2
X40: 120 | Y40: 520000 | Z40: 320877.4 | AA40: 29 | AB40: 3.4018119 | AC40: 1026600 | AD40: 2
...

Sheet Postores
A1: 61903 | B1: 388620 | C1: 362466 | D1: 390554 | E1: 392233 | F1: 184418 | G1: 286158 | H1: 60522 | I1: 385674 | J1: 390914 | K1: 61853 | L1: 391873 | M1: 184824 | N1: 2453 | O1: 369538 | P1: 367431 | Q1: 211221 | R1: 60267 | S1: 380409 | T1: 59202 | U1: 178724 | V1: 329939 | W1: 385153 | X1: 151276 | Y1: 64564 | Z1: 65085 | AA1: 259255 | AB1: 2675 | AC1: 385506 | AD1: 134565
A2: 4 | B2: 3 | C2: 2 | D2: 1 | E2: 1 | F2: 1 | G2: 1 | H2: 4 | I2: 1 | J2: 2 | K2: 1 | L2: 1 | M2: 1 | N2: 2 | O2: 1 | P2: 1 | Q2: 1 | R2: 1 | S2: 1 | T2: 2 | U2: 1 | V2: 1 | W2: 2 | X2: 1 | Y2: 1 | Z2: 1 | AA2: 2 | AB2: 1 | AC2: 1 | AD2: 1
A3: 5 | B3: 5 | C3: 3 | D3: 3 | E3: 2 | F3: 2 | G3: 1 | H3: 5 | I3: 2 | J3: 3 | K3: 2 | L3: 1 | M3: 1 | N3: 2 | O3: 2 | P3: 1 | Q3: 2 | R3: 1 | S3: 1 | T3: 2 | U3: 1 | V3: 2 | W3: 2 | X3: 1 | Y3: 1 | Z3: 1 | AA3: 2 | AB3: 1 | AC3: 1 | AD3: 1
A4: 5 | B4: 7 | C4: 3 | D4: 3 | E4: 2 | F4: 2 | G4: 1 | H4: 6 | I4: 3 | J4: 3 | K4: 2 | L4: 2 | M4: 1 | N4: 2 | O4: 3 | P4: 2 | Q4: 2 | R4: 1 | S4: 1 | T4: 5 | U4: 1 | V4: 3 | W4: 3 | X4: 1 | Y4: 1 | Z4: 1 | AA4: 2 | AB4: 1 | AC4: 1 | AD4: 1
A5: 5 | B5: 11 | C5: 3 | D5: 4 | E5: 3 | F5: 3 | G5: 1 | H5: 7 | I5: 3 | J5: 3 | K5: 3 | L5: 3 | M5: 1 | N5: 3 | O5: 3 | P5: 2 | Q5: 2 | R5: 1 | S5: 1 | T5: 5 | U5: 1 | V5: 3 | W5: 3 | X5: 1 | Y5: 1 | Z5: 1 | AA5: 2 | AB5: 1 | AC5: 1 | AD5: 1
A6: 6 | C6: 3 | D6: 8 | E6: 3 | F6: 3 | G6: 3 | H6: 7 | I6: 3 | J6: 3 | K6: 3 | L6: 3 | M6: 1 | N6: 3 | O6: 3 | P6: 2 | Q6: 3 | R6: 1 | S6: 1 | T6: 5 | U6: 1 | V6: 4 | W6: 3 | X6: 2 | Y6: 1 | Z6: 1 | AA6: 2 | AB6: 1 | AC6: 1 | AD6: 1
E7: 4 | F7: 6 | G7: 3 | H7: 7 | I7: 4 | J7: 4 | K7: 3 | L7: 4 | M7: 1 | N7: 3 | O7: 3 | P7: 2 | Q7: 3 | R7: 2 | S7: 2 | T7: 5 | U7: 1 | V7: 4 | W7: 3 | X7: 2 | Y7: 1 | Z7: 1 | AA7: 2 | AB7: 1 | AC7: 1 | AD7: 1
G8: 3 | H8: 7 | I8: 4 | J8: 7 | K8: 3 | L8: 4 | M8: 2 | N8: 3 | O8: 3 | P8: 2 | Q8: 3 | R8: 3 | S8: 3 | T8: 6 | U8: 1 | V8: 4 | W8: 3 | X8: 2 | Y8: 1 | Z8: 1 | AA8: 2 | AB8: 1 | AC8: 1 | AD8: 1
G9: 14 | H9: 17 | I9: 6 | J9: 10 | K9: 3 | L9: 4 | M9: 3 | N9: 3 | O9: 4 | P9: 2 | Q9: 3 | R9: 3 | S9: 3 | T9: 6 | U9: 1 | V9: 4 | W9: 3 | X9: 2 | Y9: 1 | Z9: 1 | AA9: 2 | AB9: 1 | AC9: 1 | AD9: 1
I10: 12 | J10: 20 | K10: 3 | L10: 5 | M10: 4 | N10: 4 | O10: 4 | P10: 2 | Q10: 3 | R10: 3 | S10: 3 | T10: 6 | U10: 1 | V10: 5 | W10: 3 | X10: 2 | Y10: 1 | Z10: 1 | AA10: 3 | AB10: 1 | AC10: 1 | AD10: 1
K11: 8 | L11: 6 | M11: 5 | N11: 5 | O11: 4 | P11: 2 | Q11: 4 | R11: 3 | S11: 3 | T11: 8 | U11: 1 | V11: 5 | W11: 3 | X11: 2 | Y11: 1 | Z11: 1 | AA11: 3 | AB11: 1 | AC11: 1 | AD11: 1
L12: 6 | M12: 7 | N12: 6 | O12: 5 | P12: 3 | Q12: 5 | R12: 3 | S12: 3 | T12: 9 | U12: 1 | V12: 5 | W12: 3 | X12: 2 | Y12: 1 | Z12: 1 | AA12: 3 | AB12: 1 | AC12: 1 | AD12: 1
P13: 4 | Q13: 6 | R13: 4 | S13: 4 | T13: 10 | U13: 1 | V13: 5 | W13: 4 | X13: 2 | Y13: 1 | Z13: 1 | AA13: 3 | AB13: 1 | AC13: 1 | AD13: 1
S14: 4 | T14: 12 | U14: 1 | V14: 5 | W14: 4 | X14: 2 | Y14: 1 | Z14: 1 | AA14: 3 | AB14: 1 | AC14: 1 | AD14: 1
S15: 6 | T15: 12 | U15: 1 | V15: 6 | W15: 4 | X15: 2 | Y15: 1 | Z15: 1 | AA15: 3 | AB15: 1 | AC15: 1 | AD15: 1
S16: 6 | T16: 14 | U16: 1 | V16: 6 | W16: 5 | X16: 3 | Y16: 1 | Z16: 1 | AA16: 3 | AB16: 1 | AC16: 1 | AD16: 1
S17: 6 | T17: 14 | U17: 1 | V17: 6 | W17: 5 | X17: 3 | Y17: 1 | Z17: 1 | AA17: 3 | AB17: 2 | AC17: 1 | AD17: 1
T18: 14 | U18: 1 | V18: 6 | W18: 5 | X18: 3 | Y18: 1 | Z18: 1 | AA18: 3 | AB18: 2 | AC18: 1 | AD18: 1
U19: 1 | V19: 6 | W19: 5 | X19: 3 | Y19: 1 | Z19: 1 | AA19: 3 | AB19: 3 | AC19: 1 | AD19: 1
U20: 1 | V20: 6 | W20: 5 | X20: 3 | Y20: 1 | Z20: 1 | AA20: 3 | AB20: 3 | AC20: 1 | AD20: 1
U21: 1 | V21: 7 | W21: 6 | X21: 3 | Y21: 1 | Z21: 1 | AA21: 3 | AB21: 3 | AC21: 1 | AD21: 1
U22: 1 | V22: 7 | W22: 6 | X22: 3 | Y22: 1 | Z22: 1 | AA22: 3 | AB22: 3 | AC22: 1 | AD22: 1
U23: 1 | V23: 7 | W23: 6 | X23: 3 | Y23: 1 | Z23: 1 | AA23: 3 | AB23: 3 | AC23: 1 | AD23: 1
U24: 1 | V24: 7 | W24: 6 | X24: 3 | Y24: 1 | Z24: 1 | AA24: 3 | AB24: 3 | AC24: 1 | AD24: 1
U25: 2 | V25: 8 | W25: 7 | X25: 3 | Y25: 1 | Z25: 1 | AA25: 3 | AB25: 3 | AC25: 1 | AD25: 1
U26: 2 | V26: 8 | W26: 7 | X26: 3 | Y26: 1 | Z26: 1 | AA26: 4 | AB26: 3 | AC26: 1 | AD26: 1
U27: 2 | V27: 8 | W27: 8 | X27: 3 | Y27: 1 | Z27: 1 | AA27: 4 | AB27: 3 | AC27: 1 | AD27: 1
U28: 3 | V28: 8 | W28: 8 | X28: 3 | Y28: 1 | Z28: 1 | AA28: 4 | AB28: 3 | AC28: 1 | AD28: 1
U29: 3 | V29: 8 | W29: 9 | X29: 3 | Y29: 1 | Z29: 1 | AA29: 4 | AB29: 3 | AC29: 1 | AD29: 1
U30: 4 | V30: 9 | W30: 10 | X30: 3 | Y30: 1 | Z30: 1 | AA30: 4 | AB30: 4 | AC30: 1 | AD30: 1
U31: 4 | V31: 9 | W31: 10 | X31: 3 | Y31: 1 | Z31: 1 | AA31: 4 | AB31: 4 | AC31: 1 | AD31: 1
V32: 9 | W32: 11 | X32: 3 | Y32: 1 | Z32: 1 | AA32: 4 | AB32: 4 | AC32: 1 | AD32: 1
V33: 11 | W33: 12 | X33: 3 | Y33: 1 | Z33: 1 | AA33: 4 | AB33: 4 | AC33: 1 | AD33: 1
W34: 13 | X34: 3 | Y34: 1 | Z34: 1 | AA34: 4 | AB34: 4 | AC34: 1 | AD34: 1
X35: 3 | Y35: 1 | Z35: 1 | AA35: 4 | AB35: 4 | AC35: 1 | AD35: 1
X36: 3 | Y36: 1 | Z36: 1 | AA36: 4 | AB36: 4 | AC36: 1 | AD36: 1
X37: 3 | Y37: 1 | Z37: 1 | AA37: 4 | AB37: 5 | AC37: 1 | AD37: 1
X38: 3 | Y38: 2 | Z38: 1 | AA38: 4 | AB38: 5 | AC38: 1 | AD38: 1
X39: 3 | Y39: 2 | Z39: 1 | AA39: 4 | AB39: 5 | AC39: 1 | AD39: 1
X40: 3 | Y40: 2 | Z40: 1 | AA40: 4 | AB40: 6 | AC40: 1 | AD40: 1
...

Sheet Departamentos
A1: 61903 | B1: 388620 | C1: 362466 | D1: 390554 | E1: 392233 | F1: 184418 | G1: 286158 | H1: 60522 | I1: 385674 | J1: 390914 | K1: 61853 | L1: 391873 | M1: 184824 | N1: 2453 | O1: 369538 | P1: 367431 | Q1: 211221 | R1: 60267 | S1: 380409 | T1: 59202 | U1: 178724 | V1: 329939 | W1: 385153 | X1: 151276 | Y1: 64564 | Z1: 65085 | AA1: 259255 | AB1: 2675 | AC1: 385506 | AD1: 134565
A2: LIMA | B2: LIMA | C2: CUSCO | D2: LIMA | E2: ANCASH | F2: LIMA | G2: LIMA | H2: LIMA | I2: LIMA | J2: HUANCAVELICA | K2: LIMA | L2: CUSCO | M2: MOQUEGUA | N2: CUSCO | O2: LIMA | P2: TUMBES | Q2: CUSCO | R2: LIMA | S2: CUSCO | T2: LIMA | U2: JUNIN | V2: AREQUIPA | W2: LIMA | X2: APURIMAC | Y2: PASCO | Z2: AREQUIPA | AA2: LA LIBERTAD | AB2: AYACUCHO | AC2: PUNO | AD2: CAJAMARCA
A3: LIMA | B3: SAN MARTIN | C3: CUSCO | D3: CUSCO | E3: ANCASH | F3: APURIMAC | G3: HUANUCO | H3: LIMA | I3: ANCASH | J3: HUANCAVELICA | K3: LIMA | L3: LIMA | M3: LIMA | N3: UCAYALI | O3: LIMA | P3: APURIMAC | Q3: APURIMAC | R3: LIMA | S3: TACNA | T3: CALLAO | U3: ICA | V3: CUSCO | W3: LIMA | X3: APURIMAC | Y3: CUSCO | Z3: JUNIN | AA3: LA LIBERTAD | AB3: AYACUCHO | AC3: PUNO | AD3: CAJAMARCA
A4: LIMA | B4: LIMA | C4: JUNIN | D4: SAN MARTIN | E4: PASCO | F4: LIMA | G4: MADRE DE DIOS | H4: LIMA | I4: LIMA | J4: PUNO | K4: LIMA | L4: MOQUEGUA | M4: CUSCO | N4: SAN MARTIN | O4: LIMA | P4: LIMA | Q4: CUSCO | R4: JUNIN | S4: LIMA | T4: PIURA | U4: LIMA | V4: CUSCO | W4: LIMA | X4: CUSCO | Y4: PUNO | Z4: ICA | AA4: CAJAMARCA | AB4: HUANCAVELICA | AC4: JUNIN | AD4: CAJAMARCA
A5: LIMA | B5: LIMA | C5: CUSCO | D5: CUSCO | E5: ANCASH | F5: LA LIBERTAD | G5: LIMA | H5: LIMA | I5: LIMA | J5: AREQUIPA | K5: LA LIBERTAD | L5: LA LIBERTAD | M5: LIMA | N5: SAN MARTIN | O5: LIMA | P5: LIMA | Q5: APURIMAC | R5: CAJAMARCA | S5: TACNA | T5: SAN MARTIN | U5: LIMA | V5: LAMBAYEQUE | W5: LA LIBERTAD | X5: CUSCO | Y5: JUNIN | Z5: CALLAO | AA5: LAMBAYEQUE | AB5: HUANCAVELICA | AC5: CUSCO | AD5: AYACUCHO
A6: LIMA | B6: CALLAO | C6: AREQUIPA | D6: ANCASH | E6: PASCO | F6: CAJAMARCA | G6: APURIMAC | H6: LIMA | I6: TACNA | J6: UCAYALI | K6: LIMA | L6: TACNA | M6: LIMA | N6: CUSCO | O6: LIMA | P6: LIMA | Q6: CUSCO | R6: ICA | S6: LIMA | T6: LAMBAYEQUE | U6: LIMA | V6: LAMBAYEQUE | W6: LIMA | X6: PUNO | Y6: HUANUCO | Z6: ANCASH | AA6: AREQUIPA | AB6: HUANCAVELICA | AC6: MADRE DE DIOS | AD6: AYACUCHO
E7: ANCASH | F7: AREQUIPA | G7: LIMA | H7: LIMA | I7: AREQUIPA | J7: AREQUIPA | K7: LIMA | L7: CUSCO | M7: LIMA | N7: CUSCO | O7: LIMA | P7: LIMA | Q7: CUSCO | R7: LIMA | S7: SAN MARTIN | T7: CUSCO | U7: LIMA | V7: LORETO | W7: LIMA | X7: PUNO | Y7: LA LIBERTAD | Z7: JUNIN | AA7: TACNA | AB7: HUANCAVELICA | AC7: CUSCO | AD7: ICA
F8: PUNO | G8: LIMA | H8: PIURA | I8: LIMA | J8: ANCASH | K8: LIMA | L8: AREQUIPA | M8: LIMA | N8: HUANUCO | O8: LIMA | P8: LIMA | Q8: APURIMAC | R8: CUSCO | S8: LIMA | T8: HUANUCO | U8: LIMA | V8: CUSCO | W8: AREQUIPA | X8: CUSCO | Y8: SAN MARTIN | Z8: HUANCAVELICA | AA8: LAMBAYEQUE | AB8: HUANCAVELICA | AC8: LA LIBERTAD | AD8: CAJAMARCA
G9: LIMA | H9: LIMA | I9: AMAZONAS | J9: AYACUCHO | K9: LIMA | L9: TACNA | M9: LIMA | N9: CUSCO | O9: LIMA | P9: LIMA | Q9: APURIMAC | R9: LIMA | S9: HUANCAVELICA | T9: SAN MARTIN | U9: AYACUCHO | V9: TACNA | W9: LIMA | X9: CUSCO | Y9: LIMA | Z9: LIMA | AA9: AREQUIPA | AB9: HUANCAVELICA | AC9: PUNO | AD9: AYACUCHO
I10: AREQUIPA | J10: ANCASH | K10: LA LIBERTAD | L10: LIMA | M10: LIMA | N10: LIMA | O10: LIMA | P10: UCAYALI | Q10: CUSCO | R10: LIMA | S10: JUNIN | T10: LIMA | U10: ICA | V10: LORETO | W10: LIMA | X10: CUSCO | Y10: APURIMAC | Z10: HUANUCO | AA10: PIURA | AB10: HUANCAVELICA | AC10: PASCO | AD10: CUSCO
K11: LIMA | L11: APURIMAC | M11: LA LIBERTAD | N11: CUSCO | O11: LIMA | P11: LIMA | Q11: MOQUEGUA | R11: LIMA | S11: LIMA | T11: SAN MARTIN | U11: LIMA | V11: TACNA | W11: LIMA | X11: CUSCO | Y11: LA LIBERTAD | Z11: AREQUIPA | AA11: LAMBAYEQUE | AB11: AYACUCHO | AC11: HUANUCO | AD11: AMAZONAS
L12: CALLAO | M12: ICA | N12: CUSCO | O12: LIMA | P12: LA LIBERTAD | Q12: CUSCO | R12: ICA | S12: PUNO | T12: PIURA | U12: LIMA | V12: LORETO | W12: LIMA | X12: CUSCO | Y12: SAN MARTIN | Z12: AMAZONAS | AA12: PIURA | AB12: JUNIN | AC12: PIURA | AD12: AYACUCHO
P13: LIMA | Q13: CUSCO | R13: LIMA | S13: LIMA | T13: HUANUCO | U13: LIMA | V13: TACNA | W13: LIMA | X13: PUNO | Y13: SAN MARTIN | Z13: ICA | AA13: PIURA | AB13: PASCO | AC13: PASCO | AD13: JUNIN
S14: CUSCO | T14: JUNIN | U14: ICA | V14: HUANUCO | W14: LIMA | X14: AREQUIPA | Y14: CAJAMARCA | Z14: LIMA | AA14: PIURA | AB14: PIURA | AC14: CUSCO | AD14: CAJAMARCA
S15: CALLAO | T15: LIMA | U15: LA LIBERTAD | V15: LAMBAYEQUE | W15: LIMA | X15: TACNA | Y15: LA LIBERTAD | Z15: ICA | AA15: AREQUIPA | AB15: CUSCO | AC15: CUSCO | AD15: CAJAMARCA
S16: ANCASH | T16: CUSCO | U16: LIMA | V16: LORETO | W16: LIMA | X16: MOQUEGUA | Y16: CAJAMARCA | Z16: MOQUEGUA | AA16: LAMBAYEQUE | AB16: LIMA | AC16: CAJAMARCA | AD16: AYACUCHO
S17: LIMA | T17: LIMA | U17: LIMA | V17: HUANUCO | W17: LIMA | X17: TACNA | Y17: PASCO | Z17: LIMA | AA17: PIURA | AB17: HUANUCO | AC17: PUNO | AD17: AYACUCHO
T18: HUANUCO | U18: LIMA | V18: HUANUCO | W18: LIMA | X18: PUNO | Y18: PASCO | Z18: LAMBAYEQUE | AA18: AREQUIPA | AB18: LA LIBERTAD | AC18: AYACUCHO | AD18: AYACUCHO
U19: LIMA | V19: LAMBAYEQUE | W19: LIMA | X19: PIURA | Y19: LORETO | Z19: PIURA | AA19: AREQUIPA | AB19: HUANCAVELICA | AC19: LIMA | AD19: AYACUCHO
U20: LAMBAYEQUE | V20: TACNA | W20: AREQUIPA | X20: TACNA | Y20: LIMA | Z20: CAJAMARCA | AA20: LAMBAYEQUE | AB20: HUANCAVELICA | AC20: AMAZONAS | AD20: AYACUCHO
U21: AYACUCHO | V21: HUANUCO | W21: LIMA | X21: AREQUIPA | Y21: CAJAMARCA | Z21: UCAYALI | AA21: LAMBAYEQUE | AB21: HUANCAVELICA | AC21: HUANUCO | AD21: CAJAMARCA
U22: ICA | V22: HUANUCO | W22: LIMA | X22: CUSCO | Y22: PIURA | Z22: AYACUCHO | AA22: LAMBAYEQUE | AB22: HUANCAVELICA | AC22: PIURA | AD22: AMAZONAS
U23: LIMA | V23: LORETO | W23: AREQUIPA | X23: PUNO | Y23: CAJAMARCA | Z23: PIURA | AA23: AREQUIPA | AB23: HUANCAVELICA | AC23: PUNO | AD23: AYACUCHO
U24: LIMA | V24: HUANUCO | W24: LIMA | X24: TACNA | Y24: SAN MARTIN | Z24: AYACUCHO | AA24: AMAZONAS | AB24: HUANCAVELICA | AC24: SAN MARTIN | AD24: TACNA
U25: AREQUIPA | V25: LAMBAYEQUE | W25: LIMA | X25: CUSCO | Y25: AREQUIPA | Z25: LIMA | AA25: LAMBAYEQUE | AB25: HUANCAVELICA | AC25: APURIMAC | AD25: AYACUCHO
U26: LIMA | V26: LAMBAYEQUE | W26: LIMA | X26: AREQUIPA | Y26: UCAYALI | Z26: MOQUEGUA | AA26: PIURA | AB26: HUANCAVELICA | AC26: LORETO | AD26: AYACUCHO
U27: LIMA | V27: LIMA | W27: LIMA | X27: CUSCO | Y27: CAJAMARCA | Z27: AYACUCHO | AA27: TUMBES | AB27: JUNIN | AC27: SAN MARTIN | AD27: CAJAMARCA
U28: ICA | V28: TACNA | W28: LIMA | X28: PUNO | Y28: UCAYALI | Z28: LORETO | AA28: AREQUIPA | AB28: JUNIN | AC28: JUNIN | AD28: AMAZONAS
U29: LIMA | V29: LORETO | W29: LIMA | X29: APURIMAC | Y29: CUSCO | Z29: PUNO | AA29: AREQUIPA | AB29: JUNIN | AC29: HUANCAVELICA | AD29: AYACUCHO
U30: LIMA | V30: LORETO | W30: CALLAO | X30: PUNO | Y30: UCAYALI | Z30: MOQUEGUA | AA30: CUSCO | AB30: JUNIN | AC30: CAJAMARCA | AD30: CAJAMARCA
U31: LIMA | V31: APURIMAC | W31: LIMA | X31: AREQUIPA | Y31: CUSCO | Z31: AYACUCHO | AA31: LAMBAYEQUE | AB31: JUNIN | AC31: PUNO | AD31: ANCASH
V32: AREQUIPA | W32: LIMA | X32: AREQUIPA | Y32: PASCO | Z32: JUNIN | AA32: AREQUIPA | AB32: APURIMAC | AC32: APURIMAC | AD32: ICA
V33: TACNA | W33: AREQUIPA | X33: CUSCO | Y33: JUNIN | Z33: PIURA | AA33: LIMA | AB33: AYACUCHO | AC33: CAJAMARCA | AD33: AMAZONAS
W34: LIMA | X34: AREQUIPA | Y34: PUNO | Z34: LORETO | AA34: AREQUIPA | AB34: AYACUCHO | AC34: CUSCO | AD34: CAJAMARCA
X35: AREQUIPA | Y35: CUSCO | Z35: LORETO | AA35: LA LIBERTAD | AB35: AYACUCHO | AC35: HUANCAVELICA | AD35: AREQUIPA
X36: CUSCO | Y36: CAJAMARCA | Z36: UCAYALI | AA36: AREQUIPA | AB36: AYACUCHO | AC36: PASCO | AD36: AYACUCHO
X37: AMAZONAS | Y37: MOQUEGUA | Z37: LIMA | AA37: PIURA | AB37: JUNIN | AC37: PUNO | AD37: CUSCO
X38: AYACUCHO | Y38: CALLAO | Z38: AREQUIPA | AA38: PIURA | AB38: JUNIN | AC38: PASCO | AD38: PUNO
X39: AMAZONAS | Y39: AYACUCHO | Z39: LIMA | AA39: LAMBAYEQUE | AB39: JUNIN | AC39: HUANCAVELICA | AD39: AREQUIPA
X40: PIURA | Y40: PIURA | Z40: CUSCO | AA40: PIURA | AB40: JUNIN | AC40: CUSCO | AD40: AYACUCHO
...
